Exception on /register [POST]
Traceback (most recent call last):
  File "/Users/aminechabane/.pyenv/versions/3.10.13/lib/python3.10/site-packages/pymysql/connections.py", line 649, in connect
    sock = socket.create_connection(
  File "/Users/aminechabane/.pyenv/versions/3.10.13/lib/python3.10/socket.py", line 824, in create_connection
    for res in getaddrinfo(host, port, 0, SOCK_STREAM):
  File "/Users/aminechabane/.pyenv/versions/3.10.13/lib/python3.10/socket.py", line 955, in getaddrinfo
    for res in _socket.getaddrinfo(host, port, family, type, proto, flags):
socket.gaierror: [Errno 8] nodename nor servname provided, or not known

During handling of the above exception, another exception occurred:

Traceback (most recent call last):
  File "/Users/aminechabane/.pyenv/versions/3.10.13/lib/python3.10/site-packages/sqlalchemy/engine/base.py", line 145, in __init__
    self._dbapi_connection = engine.raw_connection()
  File "/Users/aminechabane/.pyenv/versions/3.10.13/lib/python3.10/site-packages/sqlalchemy/engine/base.py", line 3297, in raw_connection
    return self.pool.connect()
  File "/Users/aminechabane/.pyenv/versions/3.10.13/lib/python3.10/site-packages/sqlalchemy/pool/base.py", line 449, in connect
    return _ConnectionFairy._checkout(self)
  File "/Users/aminechabane/.pyenv/versions/3.10.13/lib/python3.10/site-packages/sqlalchemy/pool/base.py", line 1264, in _checkout
    fairy = _ConnectionRecord.checkout(pool)
  File "/Users/aminechabane/.pyenv/versions/3.10.13/lib/python3.10/site-packages/sqlalchemy/pool/base.py", line 713, in checkout
    rec = pool._do_get()
  File "/Users/aminechabane/.pyenv/versions/3.10.13/lib/python3.10/site-packages/sqlalchemy/pool/impl.py", line 179, in _do_get
    with util.safe_reraise():
  File "/Users/aminechabane/.pyenv/versions/3.10.13/lib/python3.10/site-packages/sqlalchemy/util/langhelpers.py", line 224, in __exit__
    raise exc_value.with_traceback(exc_tb)
  File "/Users/aminechabane/.pyenv/versions/3.10.13/lib/python3.10/site-packages/sqlalchemy/pool/impl.py", line 177, in _do_get
    return self._create_connection()
  File "/Users/aminechabane/.pyenv/versions/3.10.13/lib/python3.10/site-packages/sqlalchemy/pool/base.py", line 390, in _create_connection
    return _ConnectionRecord(self)
  File "/Users/aminechabane/.pyenv/versions/3.10.13/lib/python3.10/site-packages/sqlalchemy/pool/base.py", line 675, in __init__
    self.__connect()
  File "/Users/aminechabane/.pyenv/versions/3.10.13/lib/python3.10/site-packages/sqlalchemy/pool/base.py", line 901, in __connect
    with util.safe_reraise():
  File "/Users/aminechabane/.pyenv/versions/3.10.13/lib/python3.10/site-packages/sqlalchemy/util/langhelpers.py", line 224, in __exit__
    raise exc_value.with_traceback(exc_tb)
  File "/Users/aminechabane/.pyenv/versions/3.10.13/lib/python3.10/site-packages/sqlalchemy/pool/base.py", line 897, in __connect
    self.dbapi_connection = connection = pool._invoke_creator(self)
  File "/Users/aminechabane/.pyenv/versions/3.10.13/lib/python3.10/site-packages/sqlalchemy/engine/create.py", line 646, in connect
    return dialect.connect(*cargs, **cparams)
  File "/Users/aminechabane/.pyenv/versions/3.10.13/lib/python3.10/site-packages/sqlalchemy/engine/default.py", line 625, in connect
    return self.loaded_dbapi.connect(*cargs, **cparams)  # type: ignore[no-any-return]  # NOQA: E501
  File "/Users/aminechabane/.pyenv/versions/3.10.13/lib/python3.10/site-packages/pymysql/connections.py", line 361, in __init__
    self.connect()
  File "/Users/aminechabane/.pyenv/versions/3.10.13/lib/python3.10/site-packages/pymysql/connections.py", line 716, in connect
    raise exc
pymysql.err.OperationalError: (2003, "Can't connect to MySQL server on 'mysql.railway.internal' ([Errno 8] nodename nor servname provided, or not known)")

The above exception was the direct cause of the following exception:

Traceback (most recent call last):
  File "/Users/aminechabane/.pyenv/versions/3.10.13/lib/python3.10/site-packages/flask/app.py", line 1511, in wsgi_app
    response = self.full_dispatch_request()
  File "/Users/aminechabane/.pyenv/versions/3.10.13/lib/python3.10/site-packages/flask/app.py", line 919, in full_dispatch_request
    rv = self.handle_user_exception(e)
  File "/Users/aminechabane/.pyenv/versions/3.10.13/lib/python3.10/site-packages/flask/app.py", line 917, in full_dispatch_request
    rv = self.dispatch_request()
  File "/Users/aminechabane/.pyenv/versions/3.10.13/lib/python3.10/site-packages/flask/app.py", line 902, in dispatch_request
    return self.ensure_sync(self.view_functions[rule.endpoint])(**view_args)  # type: ignore[no-any-return]
  File "/Users/aminechabane/Desktop/flask_app_entrainement/app.py", line 181, in register
    if User.query.filter_by(email=email).first():
  File "/Users/aminechabane/.pyenv/versions/3.10.13/lib/python3.10/site-packages/sqlalchemy/orm/query.py", line 2759, in first
    return self.limit(1)._iter().first()  # type: ignore
  File "/Users/aminechabane/.pyenv/versions/3.10.13/lib/python3.10/site-packages/sqlalchemy/orm/query.py", line 2857, in _iter
    result: Union[ScalarResult[_T], Result[_T]] = self.session.execute(
  File "/Users/aminechabane/.pyenv/versions/3.10.13/lib/python3.10/site-packages/sqlalchemy/orm/session.py", line 2365, in execute
    return self._execute_internal(
  File "/Users/aminechabane/.pyenv/versions/3.10.13/lib/python3.10/site-packages/sqlalchemy/orm/session.py", line 2241, in _execute_internal
    conn = self._connection_for_bind(bind)
  File "/Users/aminechabane/.pyenv/versions/3.10.13/lib/python3.10/site-packages/sqlalchemy/orm/session.py", line 2110, in _connection_for_bind
    return trans._connection_for_bind(engine, execution_options)
  File "<string>", line 2, in _connection_for_bind
  File "/Users/aminechabane/.pyenv/versions/3.10.13/lib/python3.10/site-packages/sqlalchemy/orm/state_changes.py", line 139, in _go
    ret_value = fn(self, *arg, **kw)
  File "/Users/aminechabane/.pyenv/versions/3.10.13/lib/python3.10/site-packages/sqlalchemy/orm/session.py", line 1189, in _connection_for_bind
    conn = bind.connect()
  File "/Users/aminechabane/.pyenv/versions/3.10.13/lib/python3.10/site-packages/sqlalchemy/engine/base.py", line 3273, in connect
    return self._connection_cls(self)
  File "/Users/aminechabane/.pyenv/versions/3.10.13/lib/python3.10/site-packages/sqlalchemy/engine/base.py", line 147, in __init__
    Connection._handle_dbapi_exception_noconnection(
  File "/Users/aminechabane/.pyenv/versions/3.10.13/lib/python3.10/site-packages/sqlalchemy/engine/base.py", line 2436, in _handle_dbapi_exception_noconnection
    raise sqlalchemy_exception.with_traceback(exc_info[2]) from e
  File "/Users/aminechabane/.pyenv/versions/3.10.13/lib/python3.10/site-packages/sqlalchemy/engine/base.py", line 145, in __init__
    self._dbapi_connection = engine.raw_connection()
  File "/Users/aminechabane/.pyenv/versions/3.10.13/lib/python3.10/site-packages/sqlalchemy/engine/base.py", line 3297, in raw_connection
    return self.pool.connect()
  File "/Users/aminechabane/.pyenv/versions/3.10.13/lib/python3.10/site-packages/sqlalchemy/pool/base.py", line 449, in connect
    return _ConnectionFairy._checkout(self)
  File "/Users/aminechabane/.pyenv/versions/3.10.13/lib/python3.10/site-packages/sqlalchemy/pool/base.py", line 1264, in _checkout
    fairy = _ConnectionRecord.checkout(pool)
  File "/Users/aminechabane/.pyenv/versions/3.10.13/lib/python3.10/site-packages/sqlalchemy/pool/base.py", line 713, in checkout
    rec = pool._do_get()
  File "/Users/aminechabane/.pyenv/versions/3.10.13/lib/python3.10/site-packages/sqlalchemy/pool/impl.py", line 179, in _do_get
    with util.safe_reraise():
  File "/Users/aminechabane/.pyenv/versions/3.10.13/lib/python3.10/site-packages/sqlalchemy/util/langhelpers.py", line 224, in __exit__
    raise exc_value.with_traceback(exc_tb)
  File "/Users/aminechabane/.pyenv/versions/3.10.13/lib/python3.10/site-packages/sqlalchemy/pool/impl.py", line 177, in _do_get
    return self._create_connection()
  File "/Users/aminechabane/.pyenv/versions/3.10.13/lib/python3.10/site-packages/sqlalchemy/pool/base.py", line 390, in _create_connection
    return _ConnectionRecord(self)
  File "/Users/aminechabane/.pyenv/versions/3.10.13/lib/python3.10/site-packages/sqlalchemy/pool/base.py", line 675, in __init__
    self.__connect()
  File "/Users/aminechabane/.pyenv/versions/3.10.13/lib/python3.10/site-packages/sqlalchemy/pool/base.py", line 901, in __connect
    with util.safe_reraise():
  File "/Users/aminechabane/.pyenv/versions/3.10.13/lib/python3.10/site-packages/sqlalchemy/util/langhelpers.py", line 224, in __exit__
    raise exc_value.with_traceback(exc_tb)
  File "/Users/aminechabane/.pyenv/versions/3.10.13/lib/python3.10/site-packages/sqlalchemy/pool/base.py", line 897, in __connect
    self.dbapi_connection = connection = pool._invoke_creator(self)
  File "/Users/aminechabane/.pyenv/versions/3.10.13/lib/python3.10/site-packages/sqlalchemy/engine/create.py", line 646, in connect
    return dialect.connect(*cargs, **cparams)
  File "/Users/aminechabane/.pyenv/versions/3.10.13/lib/python3.10/site-packages/sqlalchemy/engine/default.py", line 625, in connect
    return self.loaded_dbapi.connect(*cargs, **cparams)  # type: ignore[no-any-return]  # NOQA: E501
  File "/Users/aminechabane/.pyenv/versions/3.10.13/lib/python3.10/site-packages/pymysql/connections.py", line 361, in __init__
    self.connect()
  File "/Users/aminechabane/.pyenv/versions/3.10.13/lib/python3.10/site-packages/pymysql/connections.py", line 716, in connect
    raise exc
sqlalchemy.exc.OperationalError: (pymysql.err.OperationalError) (2003, "Can't connect to MySQL server on 'mysql.railway.internal' ([Errno 8] nodename nor servname provided, or not known)")
(Background on this error at: https://sqlalche.me/e/20/e3q8)
